Workbook

Sheet Denomination Values
A1: Denomination | B1: Number of Atomos | C1: Value in USD
A2: HYA | B2: 100 | C2: =B2 * 'Atomic Values'!$K$2 -> 0
A3: HYB | B3: 10000 | C3: =B3 * 'Atomic Values'!$K$2 -> 0
A4: HYG | B4: 100000000 | C4: =B4 * 'Atomic Values'!$K$2 -> 6.8937745e-10
A5: HYD | B5: 1e+16 | C5: =B5 * 'Atomic Values'!$K$2 -> 0.068937745
A6: HYE | B6: 1e+32 | C6: =B6 * 'Atomic Values'!$K$2 -> 689377452143789
A7: HYZ | B7: 1e+64 | C7: =B7 * 'Atomic Values'!$K$2 -> 6.89377e+46
A8: test | B8: 1e+27 | C8: =B8 * 'Atomic Values'!$K$2 -> 6893774521

Sheet Reality Constants
A1: Constant Name | B1: Constant Value
A2: Atomic Mass (kg) | B2: 1.6605391e-27
A3: Speed of Light | B3: 299792458
A4: eV/J | B4: 1.6021766e-19
A5: kWh/J | B5: 3600000
A6: Avogadro Constant | B6: 6.0221408e+23
A7: Energy Price per kWh (USD) | B7: 0.165
A8: Energy Price per J (USD) | B8: =B7/B5 -> 4.5833333e-08

Sheet Atomic Values
A1: Name | B1: Symbol | C1: Mass | D1: Abundance | E1: Atomic Mass in kg | F1: Atomic Energy (J) | G1: Atomic Energy (eV) | H1: Atomic Energy (kWh) | I1: Price per KG | J1: Atomic Price (USD) | K1: E mc2 price (USD)
A2: Hydrogen | B2: H(1) | C2: 1.007825 | D2: 99.99 | E2: =C2*'Reality Constants'!$B$2 -> 0 | F2: =E2 * ('Reality Constants'!$B$3 * 2) -> 0 | G2: =F2 / 'Reality Constants'!$B$4 -> 6.2628863 | H2: =F2 / 'Reality Constants'!$B$5 -> 0 | I2: {=IFERROR(INDEX('Price Matrix'!A:E, MATCH(B2, 'Price Matrix'!B:B, 0), 5),"")} -> 1.39 | J2: =IF(I2 = 0, "", I2 * E2) -> 0 | K2: =E2*('Reality Constants'!$B$3 * 'Reality Constants'!$B$3)*'Reality Constants'!$B$8 -> 0
A3: Hydrogen | B3: H(2) | C3: 2.014102 | D3: 0.015 | E3: =C3*'Reality Constants'!$B$2 -> 0 | F3: =E3 * ('Reality Constants'!$B$3 * 2) -> 0 | G3: =F3 / 'Reality Constants'!$B$4 -> 12.516153 | H3: =F3 / 'Reality Constants'!$B$5 -> 0 | I3: {=IFERROR(INDEX('Price Matrix'!A:E, MATCH(B3, 'Price Matrix'!B:B, 0), 5),"")} -> 13400 | J3: =IF(I3 = 0, "", I3 * E3) -> 0 | K3: =E3*('Reality Constants'!$B$3 * 'Reality Constants'!$B$3)*'Reality Constants'!$B$8 -> 0
A4: Helium | B4: He(3) | C4: 3.016029 | D4: 0.0001 | E4: =C4*'Reality Constants'!$B$2 -> 0 | F4: =E4 * ('Reality Constants'!$B$3 * 2) -> 0 | G4: =F4 / 'Reality Constants'!$B$4 -> 18.742388 | H4: =F4 / 'Reality Constants'!$B$5 -> 0 | I4: {=IFERROR(INDEX('Price Matrix'!A:E, MATCH(B4, 'Price Matrix'!B:B, 0), 5),"")} -> 20000000 | J4: =IF(I4 = 0, "", I4 * E4) -> 0 | K4: =E4*('Reality Constants'!$B$3 * 'Reality Constants'!$B$3)*'Reality Constants'!$B$8 -> 0
A5: Helium | B5: He(4) | C5: 4.002603 | D5: 100 | E5: =C5*'Reality Constants'!$B$2 -> 0 | F5: =E5 * ('Reality Constants'!$B$3 * 2) -> 0 | G5: =F5 / 'Reality Constants'!$B$4 -> 24.873215 | H5: =F5 / 'Reality Constants'!$B$5 -> 0 | I5: {=IFERROR(INDEX('Price Matrix'!A:E, MATCH(B5, 'Price Matrix'!B:B, 0), 5),"")} -> 40.39 | J5: =IF(I5 = 0, "", I5 * E5) -> 0 | K5: =E5*('Reality Constants'!$B$3 * 'Reality Constants'!$B$3)*'Reality Constants'!$B$8 -> 0
A6: Lithium | B6: Li(6) | C6: 6.015123 | D6: 7.42 | E6: =C6*'Reality Constants'!$B$2 -> 0 | F6: =E6 * ('Reality Constants'!$B$3 * 2) -> 0 | G6: =F6 / 'Reality Constants'!$B$4 -> 37.379537 | H6: =F6 / 'Reality Constants'!$B$5 -> 0 | I6: {=IFERROR(INDEX('Price Matrix'!A:E, MATCH(B6, 'Price Matrix'!B:B, 0), 5),"")} -> 85000 | J6: =IF(I6 = 0, "", I6 * E6) -> 0 | K6: =E6*('Reality Constants'!$B$3 * 'Reality Constants'!$B$3)*'Reality Constants'!$B$8 -> 0
A7: Lithium | B7: Li(7) | C7: 7.016005 | D7: 92.58 | E7: =C7*'Reality Constants'!$B$2 -> 0 | F7: =E7 * ('Reality Constants'!$B$3 * 2) -> 0 | G7: =F7 / 'Reality Constants'!$B$4 -> 43.599278 | H7: =F7 / 'Reality Constants'!$B$5 -> 0 | I7: {=IFERROR(INDEX('Price Matrix'!A:E, MATCH(B7, 'Price Matrix'!B:B, 0), 5),"")} -> 8.84 | J7: =IF(I7 = 0, "", I7 * E7) -> 0 | K7: =E7*('Reality Constants'!$B$3 * 'Reality Constants'!$B$3)*'Reality Constants'!$B$8 -> 0
A8: Beryllium | B8: Be(9) | C8: 9.012183 | D8: 100 | E8: =C8*'Reality Constants'!$B$2 -> 0 | F8: =E8 * ('Reality Constants'!$B$3 * 2) -> 0 | G8: =F8 / 'Reality Constants'!$B$4 -> 56.004046 | H8: =F8 / 'Reality Constants'!$B$5 -> 0 | I8: {=IFERROR(INDEX('Price Matrix'!A:E, MATCH(B8, 'Price Matrix'!B:B, 0), 5),"")} -> 275 | J8: =IF(I8 = 0, "", I8 * E8) -> 0 | K8: =E8*('Reality Constants'!$B$3 * 'Reality Constants'!$B$3)*'Reality Constants'!$B$8 -> 0
A9: Boron | B9: B(10) | C9: 10.012938 | D9: 19.8 | E9: =C9*'Reality Constants'!$B$2 -> 0 | F9: =E9 * ('Reality Constants'!$B$3 * 2) -> 0 | G9: =F9 / 'Reality Constants'!$B$4 -> 62.222998 | H9: =F9 / 'Reality Constants'!$B$5 -> 0 | I9: {=IFERROR(INDEX('Price Matrix'!A:E, MATCH(B9, 'Price Matrix'!B:B, 0), 5),"")} | J9: =IF(I9 = 0, "", I9 * E9) | K9: =E9*('Reality Constants'!$B$3 * 'Reality Constants'!$B$3)*'Reality Constants'!$B$8 -> 0
A10: Boron | B10: B(11) | C10: 11.009305 | D10: 80.2 | E10: =C10*'Reality Constants'!$B$2 -> 0 | F10: =E10 * ('Reality Constants'!$B$3 * 2) -> 0 | G10: =F10 / 'Reality Constants'!$B$4 -> 68.414681 | H10: =F10 / 'Reality Constants'!$B$5 -> 0 | I10: {=IFERROR(INDEX('Price Matrix'!A:E, MATCH(B10, 'Price Matrix'!B:B, 0), 5),"")} -> 8.5 | J10: =IF(I10 = 0, "", I10 * E10) -> 0 | K10: =E10*('Reality Constants'!$B$3 * 'Reality Constants'!$B$3)*'Reality Constants'!$B$8 -> 0
A11: Carbon | B11: C(12) | C11: 12 | D11: 98.9 | E11: =C11*'Reality Constants'!$B$2 -> 0 | F11: =E11 * ('Reality Constants'!$B$3 * 2) -> 0 | G11: =F11 / 'Reality Constants'!$B$4 -> 74.571117 | H11: =F11 / 'Reality Constants'!$B$5 -> 0 | I11: {=IFERROR(INDEX('Price Matrix'!A:E, MATCH(B11, 'Price Matrix'!B:B, 0), 5),"")} -> 0.53 | J11: =IF(I11 = 0, "", I11 * E11) -> 0 | K11: =E11*('Reality Constants'!$B$3 * 'Reality Constants'!$B$3)*'Reality Constants'!$B$8 -> 0
A12: Carbon | B12: C(13) | C12: 13.003355 | D12: 1.1 | E12: =C12*'Reality Constants'!$B$2 -> 0 | F12: =E12 * ('Reality Constants'!$B$3 * 2) -> 0 | G12: =F12 / 'Reality Constants'!$B$4 -> 80.806226 | H12: =F12 / 'Reality Constants'!$B$5 -> 0 | I12: {=IFERROR(INDEX('Price Matrix'!A:E, MATCH(B12, 'Price Matrix'!B:B, 0), 5),"")} | J12: =IF(I12 = 0, "", I12 * E12) | K12: =E12*('Reality Constants'!$B$3 * 'Reality Constants'!$B$3)*'Reality Constants'!$B$8 -> 0
A13: Nitrogen | B13: N(14) | C13: 14.003074 | D13: 99.63 | E13: =C13*'Reality Constants'!$B$2 -> 0 | F13: =E13 * ('Reality Constants'!$B$3 * 2) -> 0 | G13: =F13 / 'Reality Constants'!$B$4 -> 87.018739 | H13: =F13 / 'Reality Constants'!$B$5 -> 0 | I13: {=IFERROR(INDEX('Price Matrix'!A:E, MATCH(B13, 'Price Matrix'!B:B, 0), 5),"")} -> 0.11 | J13: =IF(I13 = 0, "", I13 * E13) -> 0 | K13: =E13*('Reality Constants'!$B$3 * 'Reality Constants'!$B$3)*'Reality Constants'!$B$8 -> 0
... A288: Uranium | B288: U(238) | C288: 238.05079 | D288: 99.27 | E288: =C288*'Reality Constants'!$B$2 -> 0 | F288: =E288 * ('Reality Constants'!$B$3 * 2) -> 0 | G288: =F288 / 'Reality Constants'!$B$4 -> 1479.3094 | H288: =F288 / 'Reality Constants'!$B$5 -> 0 | I288: {=IFERROR(INDEX('Price Matrix'!A:E, MATCH(B288, 'Price Matrix'!B:B, 0), 5),"")} -> 158.6 | J288: =IF(I288 = 0, "", I288 * E288) -> 0 | K288: =E288*('Reality Constants'!$B$3 * 'Reality Constants'!$B$3)*'Reality Constants'!$B$8 -> 0
D289: =AVERAGE(Atomic_Values[Abundance]) -> 28.919589 | E289: =AVERAGE(Atomic_Values[Atomic Mass in kg]) -> 0 | F289: =AVERAGE(Atomic_Values[Atomic Energy (J)]) -> 0 | G289: =AVERAGE(Atomic_Values[Atomic Energy (eV)]) -> 695.55626 | H289: =AVERAGE(Atomic_Values[Atomic Energy (kWh)]) -> 0 | I289: =AVERAGE(Atomic_Values[Price per KG]) -> 88928.004 | J289: =AVERAGE(Atomic_Values[Atomic Price (USD)]) -> 0 | K289: =AVERAGE(Atomic_Values[E mc2 price (USD)]) -> 0

Sheet Price Matrix
A1: Name | B1: Symbol | C1: Mass | D1: Abund. | E1: Price per kg | F1: Source / Details
A2: Hydrogen | B2: H(1) | C2: 1.007825 | D2: 99.99 | E2: 1.39 | F2: Industrial hydrogen gas - DOE pricing (August 2025)
A3: Hydrogen | B3: H(2) | C3: 2.014102 | D3: 0.015 | E3: 13400 | F3: Cambridge Isotope Laboratories - deuterium (August 2025)
A4: Helium | B4: He(3) | C4: 3.016029 | D4: 0.0001 | E4: 20000000 | F4: Interlune lunar mining project estimate (August 2025)
A5: Helium | B5: He(4) | C5: 4.002603 | D5: 100 | E5: 40.39 | F5: Noble gas market pricing (August 2025)
A6: Lithium | B6: Li(6) | C6: 6.015123 | D6: 7.42 | E6: 85000 | F6: Nuclear materials market - enriched Li-6 (August 2025)
A7: Lithium | B7: Li(7) | C7: 7.016005 | D7: 92.58 | E7: 8.84 | F7: Shanghai Metal Market - lithium carbonate (August 11, 2025)
A8: Beryllium | B8: Be(9) | C8: 9.012183 | D8: 100 | E8: 275 | F8: Industrial beryllium metal pricing (August 2025)
A9: Boron | B9: B(10) | C9: 10.012938 | D9: 19.8 | F9: Enriched boron-10 - specialized suppliers (August 2025)
A10: Boron | B10: B(11) | C10: 11.009305 | D10: 80.2 | E10: 8.5 | F10: Industrial boric acid pricing (August 2025)
A11: Carbon | B11: C(12) | C11: 12 | D11: 98.9 | E11: 0.53 | F11: Industrial carbon/graphite (August 2025)
A12: Carbon | B12: C(13) | C12: 13.003355 | D12: 1.1 | F12: Cambridge Isotopes - pricing varies by compound (August 2025)
A13: Nitrogen | B13: N(14) | C13: 14.003074 | D13: 99.63 | E13: 0.11 | F13: Industrial nitrogen gas (August 2025)
A14: Nitrogen | B14: N(15) | C14: 15.000109 | D14: 0.37 | E14: 1310 | F14: Sigma Aldrich - calculated from pricing (August 2025)
A15: Oxygen | B15: O(16) | C15: 15.994915 | D15: 99.76 | E15: 0.08 | F15: Industrial oxygen gas (August 2025)
A16: Oxygen | B16: O(17) | C16: 16.999131 | D16: 0.038 | F16: Minor isotope - research quantities only
A17: Oxygen | B17: O(18) | C17: 17.999159 | D17: 0.2 | F17: Medical isotope applications - specialized suppliers
A18: Fluorine | B18: F(19) | C18: 18.998403 | D18: 100 | E18: 15 | F18: Industrial fluorine gas pricing (August 2025)
A19: Neon | B19: Ne(20) | C19: 19.992439 | D19: 90.6 | E19: 2 | F19: Industrial neon gas (August 2025)
A20: Neon | B20: Ne(21) | C20: 20.993845 | D20: 0.26 | F20: Trace isotope - research quantities only
A21: Neon | B21: Ne(22) | C21: 21.991384 | D21: 9.2 | F21: Minor isotope - research use only
A22: Sodium | B22: Na(23) | C22: 22.98977 | D22: 100 | E22: 1.5 | F22: Industrial sodium metal (August 2025)
A23: Magnesium | B23: Mg(24) | C23: 23.985045 | D23: 78.9 | E23: 2.5 | F23: Industrial magnesium metal (August 2025)
A24: Magnesium | B24: Mg(25) | C24: 24.985839 | D24: 10 | F24: Enriched isotope - specialized suppliers
A25: Magnesium | B25: Mg(26) | C25: 25.982595 | D25: 11.1 | F25: Enriched isotope - specialized suppliers
A26: Aluminum | B26: Al(27) | C26: 26.981541 | D26: 100 | E26: 2.58 | F26: London Metal Exchange (August 11, 2025)
A27: Silicon | B27: Si(28) | C27: 27.976928 | D27: 92.23 | E27: 1.2 | F27: Industrial silicon metal (August 2025)
A28: Silicon | B28: Si(29) | C28: 28.976496 | D28: 4.67 | F28: Minor isotope - specialized applications
A29: Silicon | B29: Si(30) | C29: 29.973772 | D29: 3.1 | F29: Minor isotope - specialized applications
A30: Phosphorus | B30: P(31) | C30: 30.973763 | D30: 100 | E30: 2.8 | F30: Industrial phosphorus (August 2025)
A31: Sulfur | B31: S(32) | C31: 31.972072 | D31: 95.02 | E31: 0.15 | F31: Industrial sulfur (August 2025)
A32: Sulfur | B32: S(33) | C32: 32.971459 | D32: 0.75 | F32: Minor isotope - trace quantities only
A33: Sulfur | B33: S(34) | C33: 33.967868 | D33: 4.21 | F33: Minor isotope - research use only
A34: Sulfur | B34: S(36) | C34: 35.967079 | D34: 0.02 | F34: Trace isotope - research use only
A35: Chlorine | B35: Cl(35) | C35: 34.968853 | D35: 75.77 | E35: 0.25 | F35: Industrial chlorine gas (August 2025)
A36: Chlorine | B36: Cl(37) | C36: 36.965903 | D36: 24.23 | F36: Minor isotope - specialized suppliers
A37: Argon | B37: Ar(36) | C37: 35.967546 | D37: 0.34 | F37: Minor isotope - research quantities only
A38: Argon | B38: Ar(38) | C38: 37.962732 | D38: 0.063 | F38: Minor isotope - research quantities only
A39: Argon | B39: Ar(40) | C39: 39.962383 | D39: 99.6 | E39: 1.5 | F39: Industrial argon gas (August 2025)
A40: Potassium | B40: K(39) | C40: 38.963708 | D40: 93.2 | E40: 2.5 | F40: Industrial potassium compounds (August 2025)
...

Sheet Copy of Atomic Values
A1: Name | B1: Symbol | C1: Mass | D1: Abundance | E1: Atomic Mass in kg | F1: Atomic Energy (J) | G1: Atomic Energy (eV) | H1: Atomic Energy (kWh) | I1: Price per KG | J1: Atomic Price (USD) | K1: Atomic Price Weighted (USD)
A2: Hydrogen | B2: H-1 | C2: 1.007825 | D2: 99.9885 | E2: =C2*'Reality Constants'!$B$2 -> 0 | F2: =E2 * ('Reality Constants'!$B$3 * 2) -> 0 | G2: =F2 / 'Reality Constants'!$B$4 -> 6.2628863 | H2: =F2 / 'Reality Constants'!$B$5 -> 0 | I2: {=IFERROR(INDEX(all_stable_isotopes_complete_no!A:E, MATCH(B2, all_stable_isotopes_complete_no!B:B, 0), 5),"")} -> 1.5 | J2: =IF(I2 = 0, "", I2 * E2) -> 0 | K2: =IF(I2 = 0, "", (I2 * E2) *(D2 / 100)) -> 0
A3: Hydrogen | B3: H-2 | C3: 2.014102 | D3: 0.0115 | E3: =C3*'Reality Constants'!$B$2 -> 0 | F3: =E3 * ('Reality Constants'!$B$3 * 2) -> 0 | G3: =F3 / 'Reality Constants'!$B$4 -> 12.516153 | H3: =F3 / 'Reality Constants'!$B$5 -> 0 | I3: {=IFERROR(INDEX(all_stable_isotopes_complete_no!A:E, MATCH(B3, all_stable_isotopes_complete_no!B:B, 0), 5),"")} -> 13400 | J3: =IF(I3 = 0, "", I3 * E3) -> 0 | K3: =IF(I3 = 0, "", (I3 * E3) *(D3 / 100)) -> 0
A4: Helium | B4: He-3 | C4: 3.016029 | D4: 0.000137 | E4: =C4*'Reality Constants'!$B$2 -> 0 | F4: =E4 * ('Reality Constants'!$B$3 * 2) -> 0 | G4: =F4 / 'Reality Constants'!$B$4 -> 18.742388 | H4: =F4 / 'Reality Constants'!$B$5 -> 0 | I4: {=IFERROR(INDEX(all_stable_isotopes_complete_no!A:E, MATCH(B4, all_stable_isotopes_complete_no!B:B, 0), 5),"")} -> 1000000 | J4: =IF(I4 = 0, "", I4 * E4) -> 0 | K4: =IF(I4 = 0, "", (I4 * E4) *(D4 / 100)) -> 0
A5: Helium | B5: He-4 | C5: 4.002603 | D5: 99.999863 | E5: =C5*'Reality Constants'!$B$2 -> 0 | F5: =E5 * ('Reality Constants'!$B$3 * 2) -> 0 | G5: =F5 / 'Reality Constants'!$B$4 -> 24.873215 | H5: =F5 / 'Reality Constants'!$B$5 -> 0 | I5: {=IFERROR(INDEX(all_stable_isotopes_complete_no!A:E, MATCH(B5, all_stable_isotopes_complete_no!B:B, 0), 5),"")} -> 40 | J5: =IF(I5 = 0, "", I5 * E5) -> 0 | K5: =IF(I5 = 0, "", (I5 * E5) *(D5 / 100)) -> 0
A6: Lithium | B6: Li-6 | C6: 6.015123 | D6: 7.42 | E6: =C6*'Reality Constants'!$B$2 -> 0 | F6: =E6 * ('Reality Constants'!$B$3 * 2) -> 0 | G6: =F6 / 'Reality Constants'!$B$4 -> 37.379537 | H6: =F6 / 'Reality Constants'!$B$5 -> 0 | I6: {=IFERROR(INDEX(all_stable_isotopes_complete_no!A:E, MATCH(B6, all_stable_isotopes_complete_no!B:B, 0), 5),"")} -> 85000 | J6: =IF(I6 = 0, "", I6 * E6) -> 0 | K6: =IF(I6 = 0, "", (I6 * E6) *(D6 / 100)) -> 0
A7: Lithium | B7: Li-7 | C7: 7.016005 | D7: 92.58 | E7: =C7*'Reality Constants'!$B$2 -> 0 | F7: =E7 * ('Reality Constants'!$B$3 * 2) -> 0 | G7: =F7 / 'Reality Constants'!$B$4 -> 43.599278 | H7: =F7 / 'Reality Constants'!$B$5 -> 0 | I7: {=IFERROR(INDEX(all_stable_isotopes_complete_no!A:E, MATCH(B7, all_stable_isotopes_complete_no!B:B, 0), 5),"")} -> 12.85 | J7: =IF(I7 = 0, "", I7 * E7) -> 0 | K7: =IF(I7 = 0, "", (I7 * E7) *(D7 / 100)) -> 0
A8: Beryllium | B8: Be-9 | C8: 9.012183 | D8: 100 | E8: =C8*'Reality Constants'!$B$2 -> 0 | F8: =E8 * ('Reality Constants'!$B$3 * 2) -> 0 | G8: =F8 / 'Reality Constants'!$B$4 -> 56.004046 | H8: =F8 / 'Reality Constants'!$B$5 -> 0 | I8: {=IFERROR(INDEX(all_stable_isotopes_complete_no!A:E, MATCH(B8, all_stable_isotopes_complete_no!B:B, 0), 5),"")} -> 275 | J8: =IF(I8 = 0, "", I8 * E8) -> 0 | K8: =IF(I8 = 0, "", (I8 * E8) *(D8 / 100)) -> 0
A9: Boron | B9: B-10 | C9: 10.012938 | D9: 19.9 | E9: =C9*'Reality Constants'!$B$2 -> 0 | F9: =E9 * ('Reality Constants'!$B$3 * 2) -> 0 | G9: =F9 / 'Reality Constants'!$B$4 -> 62.222998 | H9: =F9 / 'Reality Constants'!$B$5 -> 0 | I9: {=IFERROR(INDEX(all_stable_isotopes_complete_no!A:E, MATCH(B9, all_stable_isotopes_complete_no!B:B, 0), 5),"")} -> 8500 | J9: =IF(I9 = 0, "", I9 * E9) -> 0 | K9: =IF(I9 = 0, "", (I9 * E9) *(D9 / 100)) -> 0
A10: Boron | B10: B-11 | C10: 11.009305 | D10: 80.1 | E10: =C10*'Reality Constants'!$B$2 -> 0 | F10: =E10 * ('Reality Constants'!$B$3 * 2) -> 0 | G10: =F10 / 'Reality Constants'!$B$4 -> 68.414681 | H10: =F10 / 'Reality Constants'!$B$5 -> 0 | I10: {=IFERROR(INDEX(all_stable_isotopes_complete_no!A:E, MATCH(B10, all_stable_isotopes_complete_no!B:B, 0), 5),"")} -> 8.5 | J10: =IF(I10 = 0, "", I10 * E10) -> 0 | K10: =IF(I10 = 0, "", (I10 * E10) *(D10 / 100)) -> 0
A11: Carbon | B11: C-12 | C11: 12 | D11: 98.93 | E11: =C11*'Reality Constants'!$B$2 -> 0 | F11: =E11 * ('Reality Constants'!$B$3 * 2) -> 0 | G11: =F11 / 'Reality Constants'!$B$4 -> 74.571117 | H11: =F11 / 'Reality Constants'!$B$5 -> 0 | I11: {=IFERROR(INDEX(all_stable_isotopes_complete_no!A:E, MATCH(B11, all_stable_isotopes_complete_no!B:B, 0), 5),"")} -> 0.53 | J11: =IF(I11 = 0, "", I11 * E11) -> 0 | K11: =IF(I11 = 0, "", (I11 * E11) *(D11 / 100)) -> 0
A12: Carbon | B12: C-13 | C12: 13.003355 | D12: 1.07 | E12: =C12*'Reality Constants'!$B$2 -> 0 | F12: =E12 * ('Reality Constants'!$B$3 * 2) -> 0 | G12: =F12 / 'Reality Constants'!$B$4 -> 80.806226 | H12: =F12 / 'Reality Constants'!$B$5 -> 0 | I12: {=IFERROR(INDEX(all_stable_isotopes_complete_no!A:E, MATCH(B12, all_stable_isotopes_complete_no!B:B, 0), 5),"")} -> 8000 | J12: =IF(I12 = 0, "", I12 * E12) -> 0 | K12: =IF(I12 = 0, "", (I12 * E12) *(D12 / 100)) -> 0
A13: Nitrogen | B13: N-14 | C13: 14.003074 | D13: 99.632 | E13: =C13*'Reality Constants'!$B$2 -> 0 | F13: =E13 * ('Reality Constants'!$B$3 * 2) -> 0 | G13: =F13 / 'Reality Constants'!$B$4 -> 87.018739 | H13: =F13 / 'Reality Constants'!$B$5 -> 0 | I13: {=IFERROR(INDEX(all_stable_isotopes_complete_no!A:E, MATCH(B13, all_stable_isotopes_complete_no!B:B, 0), 5),"")} -> 0.11 | J13: =IF(I13 = 0, "", I13 * E13) -> 0 | K13: =IF(I13 = 0, "", (I13 * E13) *(D13 / 100)) -> 0
... A286: Uranium | B286: U-238 | C286: 238.05079 | D286: 99.2742 | E286: =C286*'Reality Constants'!$B$2 -> 0 | F286: =E286 * ('Reality Constants'!$B$3 * 2) -> 0 | G286: =F286 / 'Reality Constants'!$B$4 -> 1479.3094 | H286: =F286 / 'Reality Constants'!$B$5 -> 0 | I286: {=IFERROR(INDEX(all_stable_isotopes_complete_no!A:E, MATCH(B286, all_stable_isotopes_complete_no!B:B, 0), 5),"")} -> 158.6 | J286: =IF(I286 = 0, "", I286 * E286) -> 0 | K286: =IF(I286 = 0, "", (I286 * E286) *(D286 / 100)) -> 0
D287: =AVERAGE(Atomic_Values_2[Abundance]) -> 29.119488 | E287: =AVERAGE(Atomic_Values_2[Atomic Mass in kg]) -> 0 | F287: =AVERAGE(Atomic_Values_2[Atomic Energy (J)]) -> 0 | G287: =AVERAGE(Atomic_Values_2[Atomic Energy (eV)]) -> 698.52039 | H287: =AVERAGE(Atomic_Values_2[Atomic Energy (kWh)]) -> 0 | I287: =AVERAGE(Atomic_Values_2[Price per KG]) -> 5310.3173 | J287: =AVERAGE(Atomic_Values_2[Atomic Price (USD)]) -> 0 | K287: =AVERAGE(Atomic_Values_2[Atomic Price Weighted (USD)]) -> 0

Sheet all_stable_isotopes_complete_no
A1: Element | B1: Isotope Symbol | C1: Atomic Mass | D1: Abundance (%) | E1: Price per kg (USD) | F1: Price Source(s)
A2: Hydrogen | B2: H-1 | C2: 1.007825 | D2: 99.9885 | E2: 1.5 | F2: Industrial H2 gas pricing (Nov 2025)
A3: Hydrogen | B3: H-2 | C3: 2.014102 | D3: 0.0115 | E3: 13400 | F3: Deuterium enriched - Cambridge Labs (Nov 2025)
A4: Helium | B4: He-3 | C4: 3.016029 | D4: 0.000137 | E4: 1000000 | F4: Lunar mining estimate (Nov 2025)
A5: Helium | B5: He-4 | C5: 4.002603 | D5: 99.999863 | E5: 40 | F5: Industrial He gas pricing (Nov 2025)
A6: Lithium | B6: Li-6 | C6: 6.015123 | D6: 7.42 | E6: 85000 | F6: Nuclear enriched material (Nov 2025)
A7: Lithium | B7: Li-7 | C7: 7.016005 | D7: 92.58 | E7: 12.85 | F7: Lithium carbonate 99% (Nov 2025)
A8: Beryllium | B8: Be-9 | C8: 9.012183 | D8: 100 | E8: 275 | F8: Industrial Be metal (Nov 2025)
A9: Boron | B9: B-10 | C9: 10.012938 | D9: 19.9 | E9: 8500 | F9: Enriched B-10 specialist pricing
A10: Boron | B10: B-11 | C10: 11.009305 | D10: 80.1 | E10: 8.5 | F10: Industrial boric acid (Nov 2025)
A11: Carbon | B11: C-12 | C11: 12 | D11: 98.93 | E11: 0.53 | F11: Industrial graphite (Nov 2025)
A12: Carbon | B12: C-13 | C12: 13.003355 | D12: 1.07 | E12: 8000 | F12: C-13 enriched specialist
A13: Nitrogen | B13: N-14 | C13: 14.003074 | D13: 99.632 | E13: 0.11 | F13: Industrial N2 gas (Nov 2025)
... A286: Uranium | B286: U-238 | C286: 238.05079 | D286: 99.2742 | E286: 158.6 | F286: Trading Econ. U USD/lb (Nov 28)
